Unhandled exception on main
Traceback (most recent call last):
  File "/home/u201853/.local/lib/python3.9/site-packages/telethon/client/updates.py", line 570, in _dispatch_update
    await callback(event)
  File "/home/u201853/url/uploader.py", line 102, in main
    await link_download(event)
  File "/home/u201853/url/uploader.py", line 150, in link_download
    progress_task = asyncio.create_task(update_progress(event, message, link))
NameError: name 'update_progress' is not defined
Unhandled exception on main
Traceback (most recent call last):
  File "/home/u201853/.local/lib/python3.9/site-packages/telethon/client/updates.py", line 570, in _dispatch_update
    await callback(event)
  File "/home/u201853/url/uploader.py", line 102, in main
    await link_download(event)
  File "/home/u201853/url/uploader.py", line 140, in link_download
    total_size = sum(os.path.getsize(os.path.join(user_dir, file)) for file in os.listdir(user_dir))
OSError: [Errno 116] Stale file handle: '/home/u201853/url/6476862483'
